<?xml version="1.0"?>
<robot name="puma260">

    <link name="base_link">
        <visual>
            <origin xyz="0 0 0" rpy="0.0 0.0 0.0"/>
            <geometry>
                <mesh filename="package://puma260_description/meshes/base_link.stl"/>
                <!-- <cylinder length="0.2" radius="0.05"/> -->
            </geometry>
            <material name="white">
                <color rgba="1 1 1 1"/>
            </material>
        </visual>
    </link>

    <joint name="joint_1" type="revolute">
        <parent link="base_link"/>
        <child link="torso"/>
        <origin xyz="0.0 0.0 0.0" rpy="0.0 0.0 0.0"/>
        <limit effort="1000.0" lower="-0.195774" upper="5.366298" velocity="0.5" />
        <axis xyz="0 0 1"/>
    </joint>

    <link name="torso">
        <visual>
            <origin xyz="0.0 0.0 0.0" rpy="0.0 0.0 0.0"/>                  
            <geometry>
                <mesh filename="package://puma260_description/meshes/torso.stl"/>
                <!-- <cylinder length="0.2" radius="0.05"/> -->
            </geometry>
            <material name="white">
                <color rgba="1 1 1 1"/>
            </material>
        </visual>
    </link>

    <joint name="joint_2" type="revolute">
        <parent link="torso"/>
        <child link="arm"/>
        <origin xyz="0.0 0.0 0.3302" rpy="-1.5708 0.38 0.0 "/>
        <limit effort="1000.0" lower="-4.77369" upper="0.84636" velocity="0.5" />
        <axis xyz="0 0 1"/>
    </joint> 

    <link name="arm">
        <visual>
            <origin xyz="0.0 0.0 0.0" rpy="0.0 0.0 0.0"/>                  
            <geometry>
                <mesh filename="package://puma260_description/meshes/arm.stl"/>
                <!-- <cylinder length="0.2" radius="0.05"/> -->
            </geometry> 
            <material name="white">
                <color rgba="1 1 1 1"/>
            </material>
        </visual>

    </link>

    <joint name="joint_3" type="revolute">
        <parent link="arm"/>
        <child link="forearm"/>
        <origin xyz="0.203202 0.0 0.0" rpy="0.0 0.0 0.0"/>
        <limit effort="1000.0" lower="-4.401754" upper="0.761536" velocity="0.5" />
        <axis xyz="0 0 1"/>
    </joint> 

    <link name="forearm">
        <visual>
            <origin xyz="0.0 0.0 0.0" rpy="0.0 0.0 0.0"/>                  
            <geometry>
                <mesh filename="package://puma260_description/meshes/forearm.stl"/>
                <!-- <cylinder length="0.2" radius="0.05"/> -->
            </geometry>
            <material name="white">
                <color rgba="1 1 1 1"/>
            </material>
        </visual>
    </link>
    <joint name="joint_4" type="revolute">
        <parent link="forearm"/>
        <child link="link_dummy_1"/>
        <origin xyz="0.0 0.0 -0.12623" rpy="1.57 0.0 3.42"/>
        <limit effort="1000.0" lower="-8.727639" upper="2.425219" velocity="0.5" />
        <axis xyz="0 0 1"/>
    </joint> 

    <link name="link_dummy_1">
        <visual>
            <origin xyz="0.0 0.0 0.0" rpy="0.0 0.0 0.0"/>                  
            <geometry>
                <mesh filename="package://puma260_description/meshes/link_dummy_1.stl"/>
                <!-- <cylinder length="0.2" radius="0.05"/> -->
            </geometry>
            <material name="white">
                <color rgba="1 1 1 1"/>
            </material>
        </visual>
    </link>
    <joint name="joint_5" type="revolute">
        <parent link="link_dummy_1"/>
        <child link="link_dummy_2"/>
        <origin xyz="0.0 0.0 0.2032" rpy="-1.5708 0.0 1.57059"/>
        <limit effort="1000.0" lower="-3.154507" upper="3.955906" velocity="0.5" />
        <axis xyz="0 0 1"/>
    </joint> 

    <link name="link_dummy_2">
        <visual>
            <origin xyz="0.0 0.0 0.0" rpy="0.0 0.0 0.0"/>                  
            <geometry>
                <mesh filename="package://puma260_description/meshes/link_dummy_2.stl"/>
                <!-- <cylinder length="0.2" radius="0.05"/> -->
            </geometry> 
            <material name="white">
                <color rgba="1 1 1 1"/>
            </material>
        </visual>
    </link>
    <joint name="joint_6" type="revolute">
        <parent link="link_dummy_2"/>
        <child link="end_effector"/>
        <origin xyz="0.0 0.0 0.0" rpy="1.57 0.0 -1.57"/>
        <limit effort="1000.0" lower="-3.123938" upper="8.313073" velocity="0.5" />
        <axis xyz="0 0 1"/>
    </joint> 
    <link name="end_effector">
        <visual>
            <origin xyz="0.0 0.0 0.05537" rpy="0.0 0.0 0.0"/>                  
            <geometry>
                <mesh filename="package://puma260_description/meshes/end_effector.stl"/>
                <!-- <cylinder length="0.2" radius="0.05"/> -->
            </geometry>
            <material name="white">
                <color rgba="1 1 1 1"/>
            </material>
        </visual>
    </link>
</robot>
